Workbook

Sheet Barrido Gradientes
B3: y [N] | C3: x [mm] | H3: BARRIDO GRADIENTES
B4: 27.11119 | C4: 0 | F4: Valores aprox x [mm] | H4: Valores para el SES | N4: Y [N] | O4: x prueba[mm] | P4: aprox [mm] | R4: Fmax
B5: 64.38905 | C5: 0.074707 | F5: MIN | G5: MAX | H5: x MIN [mm] | I5: x MAX [mm] | J5: y MIN [N] | K5: y MAX [N] | L5: Gradiente [N/mm] | N5: =INDEX($B$4:$B$1298,MATCH(O5,$C$4:$C$1309,0),1) -> 2430.014 | O5: =LARGE($C$4:$C$1309,COUNTIF($C$4:$C$1309,">="&P5)) -> 1.0275267 | P5: 1 | R5: =MAX(B4:B2000) -> 21521.77
B6: 118.6114 | C6: 0.1106567 | F6: 3.75 | G6: 5.25 | H6: =IF(I6-INDEX($O$5:$O$117, MATCH(F6, $P$5:$P$117, 0))>1,INDEX($O$5:$O$117, MATCH(F6, $P$5:$P$117, 0)),INDEX($O$5:$O$117, MATCH(F6-0.02, $P$5:$P$117, 0))) -> 3.7567447 | I6: =IF(INDEX($O$5:$O$117, MATCH(G6, $P$5:$P$117, 0))-INDEX($O$5:$O$117, MATCH(F6, $P$5:$P$117, 0))>1,INDEX($O$5:$O$117, MATCH(G6, $P$5:$P$117, 0)),INDEX($O$5:$O$117, MATCH(G6+0.02, $P$5:$P$117, 0))) -> 5.2681577 | J6: =INDEX($N$5:$N$67, MATCH(H6, $O$5:$O$67, 0)) -> 9935.479 | K6: =INDEX($N$5:$N$67, MATCH(I6, $O$5:$O$67, 0)) -> 14274.2 | L6: =MAX(0, IFERROR((K6-J6)/(I6-H6), 0)) -> 2870.6389 | N6: =INDEX($B$4:$B$1298,MATCH(O6,$C$4:$C$1309,0),1) -> 3027.573 | O6: =LARGE($C$4:$C$1309,COUNTIF($C$4:$C$1309,">="&P6)) -> 1.2573857 | P6: 1.25
B7: 177.8053 | C7: 0.1434936 | F7: 3.75 | G7: 5.75 | H7: =IF(I7-INDEX($O$5:$O$117, MATCH(F7, $P$5:$P$117, 0))>1,INDEX($O$5:$O$117, MATCH(F7, $P$5:$P$117, 0)),INDEX($O$5:$O$117, MATCH(F7-0.02, $P$5:$P$117, 0))) -> 3.7567447 | I7: =IF(INDEX($O$5:$O$117, MATCH(G7, $P$5:$P$117, 0))-INDEX($O$5:$O$117, MATCH(F7, $P$5:$P$117, 0))>1,INDEX($O$5:$O$117, MATCH(G7, $P$5:$P$117, 0)),INDEX($O$5:$O$117, MATCH(G7+0.02, $P$5:$P$117, 0))) -> 5.7560727 | J7: =INDEX($N$5:$N$67, MATCH(H7, $O$5:$O$67, 0)) -> 9935.479 | K7: =INDEX($N$5:$N$67, MATCH(I7, $O$5:$O$67, 0)) -> 15668.78 | L7: =MAX(0, IFERROR((K7-J7)/(I7-H7), 0)) -> 2867.614 | N7: =INDEX($B$4:$B$1298,MATCH(O7,$C$4:$C$1309,0),1) -> 3719.395 | O7: =LARGE($C$4:$C$1309,COUNTIF($C$4:$C$1309,">="&P7)) -> 1.5181577 | P7: 1.5 | R7: Fmax > 12,7 mm
B8: 317.5163 | C8: 0.2085571 | F8: 4 | G8: 5 | H8: =IF(I8-INDEX($O$5:$O$117, MATCH(F8, $P$5:$P$117, 0))>1,INDEX($O$5:$O$117, MATCH(F8, $P$5:$P$117, 0)),INDEX($O$5:$O$117, MATCH(F8-0.02, $P$5:$P$117, 0))) -> 4.0160217 | I8: =IF(INDEX($O$5:$O$117, MATCH(G8, $P$5:$P$117, 0))-INDEX($O$5:$O$117, MATCH(F8, $P$5:$P$117, 0))>1,INDEX($O$5:$O$117, MATCH(G8, $P$5:$P$117, 0)),INDEX($O$5:$O$117, MATCH(G8+0.02, $P$5:$P$117, 0))) -> 5.0322567 | J8: =INDEX($N$5:$N$67, MATCH(H8, $O$5:$O$67, 0)) -> 10678.02 | K8: =INDEX($N$5:$N$67, MATCH(I8, $O$5:$O$67, 0)) -> 13592.11 | L8: =MAX(0, IFERROR((K8-J8)/(I8-H8), 0)) -> 2867.5356 | N8: =INDEX($B$4:$B$1298,MATCH(O8,$C$4:$C$1309,0),1) -> 4505.48 | O8: =LARGE($C$4:$C$1309,COUNTIF($C$4:$C$1309,">="&P8)) -> 1.7771297 | P8: 1.75 | R8: =IF(MAX(C4:C1298)>12.7,INDEX(B4:B1298,MATCH(LARGE($C$4:$C$1298,COUNTIF($C$4:$C$1298,">="&12.6)),C4:C1298,0)),R5) -> 21521.77 | S8: =MATCH(R8,B4:B1489,0)+14 -> 189
B9: 396.6298 | C9: 0.2414245 | F9: 4 | G9: 5.5 | H9: =IF(I9-INDEX($O$5:$O$117, MATCH(F9, $P$5:$P$117, 0))>1,INDEX($O$5:$O$117, MATCH(F9, $P$5:$P$117, 0)),INDEX($O$5:$O$117, MATCH(F9-0.02, $P$5:$P$117, 0))) -> 4.0160217 | I9: =IF(INDEX($O$5:$O$117, MATCH(G9, $P$5:$P$117, 0))-INDEX($O$5:$O$117, MATCH(F9, $P$5:$P$117, 0))>1,INDEX($O$5:$O$117, MATCH(G9, $P$5:$P$117, 0)),INDEX($O$5:$O$117, MATCH(G9+0.02, $P$5:$P$117, 0))) -> 5.5278927 | J9: =INDEX($N$5:$N$67, MATCH(H9, $O$5:$O$67, 0)) -> 10678.02 | K9: =INDEX($N$5:$N$67, MATCH(I9, $O$5:$O$67, 0)) -> 15006.95 | L9: =MAX(0, IFERROR((K9-J9)/(I9-H9), 0)) -> 2863.2932 | N9: =INDEX($B$4:$B$1298,MATCH(O9,$C$4:$C$1309,0),1) -> 5128.289 | O9: =LARGE($C$4:$C$1309,COUNTIF($C$4:$C$1309,">="&P9)) -> 2.0050047 | P9: 2
B10: 559.9065 | C10: 0.2732849 | F10: 4.25 | G10: 5.75 | H10: =IF(I10-INDEX($O$5:$O$117, MATCH(F10, $P$5:$P$117, 0))>1,INDEX($O$5:$O$117, MATCH(F10, $P$5:$P$117, 0)),INDEX($O$5:$O$117, MATCH(F10-0.02, $P$5:$P$117, 0))) -> 4.3111577 | I10: =IF(INDEX($O$5:$O$117, MATCH(G10, $P$5:$P$117, 0))-INDEX($O$5:$O$117, MATCH(F10, $P$5:$P$117, 0))>1,INDEX($O$5:$O$117, MATCH(G10, $P$5:$P$117, 0)),INDEX($O$5:$O$117, MATCH(G10+0.02, $P$5:$P$117, 0))) -> 5.7560727 | J10: =INDEX($N$5:$N$67, MATCH(H10, $O$5:$O$67, 0)) -> 11532.33 | K10: =INDEX($N$5:$N$67, MATCH(I10, $O$5:$O$67, 0)) -> 15668.78 | L10: =MAX(0, IFERROR((K10-J10)/(I10-H10), 0)) -> 2862.7636 | N10: =INDEX($B$4:$B$1298,MATCH(O10,$C$4:$C$1309,0),1) -> 5728.135 | O10: =LARGE($C$4:$C$1309,COUNTIF($C$4:$C$1309,">="&P10)) -> 2.2589107 | P10: 2.25
B11: 644.0698 | C11: 0.3382263 | F11: 3.75 | G11: 4.75 | H11: =IF(I11-INDEX($O$5:$O$117, MATCH(F11, $P$5:$P$117, 0))>1,INDEX($O$5:$O$117, MATCH(F11, $P$5:$P$117, 0)),INDEX($O$5:$O$117, MATCH(F11-0.02, $P$5:$P$117, 0))) -> 3.7567447 | I11: =IF(INDEX($O$5:$O$117, MATCH(G11, $P$5:$P$117, 0))-INDEX($O$5:$O$117, MATCH(F11, $P$5:$P$117, 0))>1,INDEX($O$5:$O$117, MATCH(G11, $P$5:$P$117, 0)),INDEX($O$5:$O$117, MATCH(G11+0.02, $P$5:$P$117, 0))) -> 4.7725217 | J11: =INDEX($N$5:$N$67, MATCH(H11, $O$5:$O$67, 0)) -> 9935.479 | K11: =INDEX($N$5:$N$67, MATCH(I11, $O$5:$O$67, 0)) -> 12842.48 | L11: =MAX(0, IFERROR((K11-J11)/(I11-H11), 0)) -> 2861.8496 | N11: =INDEX($B$4:$B$1298,MATCH(O11,$C$4:$C$1309,0),1) -> 6452.667 | O11: =LARGE($C$4:$C$1309,COUNTIF($C$4:$C$1309,">="&P11)) -> 2.5204467 | P11: 2.5
B12: 726.5497 | C12: 0.3696594 | F12: 4.5 | G12: 5.5 | H12: =IF(I12-INDEX($O$5:$O$117, MATCH(F12, $P$5:$P$117, 0))>1,INDEX($O$5:$O$117, MATCH(F12, $P$5:$P$117, 0)),INDEX($O$5:$O$117, MATCH(F12-0.02, $P$5:$P$117, 0))) -> 4.5380857 | I12: =IF(INDEX($O$5:$O$117, MATCH(G12, $P$5:$P$117, 0))-INDEX($O$5:$O$117, MATCH(F12, $P$5:$P$117, 0))>1,INDEX($O$5:$O$117, MATCH(G12, $P$5:$P$117, 0)),INDEX($O$5:$O$117, MATCH(G12+0.02, $P$5:$P$117, 0))) -> 5.5278927 | J12: =INDEX($N$5:$N$67, MATCH(H12, $O$5:$O$67, 0)) -> 12175.59 | K12: =INDEX($N$5:$N$67, MATCH(I12, $O$5:$O$67, 0)) -> 15006.95 | L12: =MAX(0, IFERROR((K12-J12)/(I12-H12), 0)) -> 2860.5173 | N12: =INDEX($B$4:$B$1298,MATCH(O12,$C$4:$C$1309,0),1) -> 7273.242 | O12: =LARGE($C$4:$C$1309,COUNTIF($C$4:$C$1309,">="&P12)) -> 2.7814327 | P12: 2.75
B13: 894.8762 | C13: 0.4360347 | F13: 3.25 | G13: 5.25 | H13: =IF(I13-INDEX($O$5:$O$117, MATCH(F13, $P$5:$P$117, 0))>1,INDEX($O$5:$O$117, MATCH(F13, $P$5:$P$117, 0)),INDEX($O$5:$O$117, MATCH(F13-0.02, $P$5:$P$117, 0))) -> 3.3009947 | I13: =IF(INDEX($O$5:$O$117, MATCH(G13, $P$5:$P$117, 0))-INDEX($O$5:$O$117, MATCH(F13, $P$5:$P$117, 0))>1,INDEX($O$5:$O$117, MATCH(G13, $P$5:$P$117, 0)),INDEX($O$5:$O$117, MATCH(G13+0.02, $P$5:$P$117, 0))) -> 5.2681577 | J13: =INDEX($N$5:$N$67, MATCH(H13, $O$5:$O$67, 0)) -> 8653.225 | K13: =INDEX($N$5:$N$67, MATCH(I13, $O$5:$O$67, 0)) -> 14274.2 | L13: =MAX(0, IFERROR((K13-J13)/(I13-H13), 0)) -> 2857.4018 | N13: =INDEX($B$4:$B$1298,MATCH(O13,$C$4:$C$1309,0),1) -> 7928.692 | O13: =LARGE($C$4:$C$1309,COUNTIF($C$4:$C$1309,">="&P13)) -> 3.0076597 | P13: 3
B14: 979.0395 | C14: 0.4686887 | F14: 4 | G14: 6 | H14: =IF(I14-INDEX($O$5:$O$117, MATCH(F14, $P$5:$P$117, 0))>1,INDEX($O$5:$O$117, MATCH(F14, $P$5:$P$117, 0)),INDEX($O$5:$O$117, MATCH(F14-0.02, $P$5:$P$117, 0))) -> 4.0160217 | I14: =IF(INDEX($O$5:$O$117, MATCH(G14, $P$5:$P$117, 0))-INDEX($O$5:$O$117, MATCH(F14, $P$5:$P$117, 0))>1,INDEX($O$5:$O$117, MATCH(G14, $P$5:$P$117, 0)),INDEX($O$5:$O$117, MATCH(G14+0.02, $P$5:$P$117, 0))) -> 6.0482487 | J14: =INDEX($N$5:$N$67, MATCH(H14, $O$5:$O$67, 0)) -> 10678.02 | K14: =INDEX($N$5:$N$67, MATCH(I14, $O$5:$O$67, 0)) -> 16484.25 | L14: =MAX(0, IFERROR((K14-J14)/(I14-H14), 0)) -> 2857.0775 | N14: =INDEX($B$4:$B$1298,MATCH(O14,$C$4:$C$1309,0),1) -> 8653.225 | O14: =LARGE($C$4:$C$1309,COUNTIF($C$4:$C$1309,">="&P14)) -> 3.3009947 | P14: 3.25
B15: 1149.049 | C15: 0.5012207 | F15: 3.5 | G15: 5.5 | H15: =IF(I15-INDEX($O$5:$O$117, MATCH(F15, $P$5:$P$117, 0))>1,INDEX($O$5:$O$117, MATCH(F15, $P$5:$P$117, 0)),INDEX($O$5:$O$117, MATCH(F15-0.02, $P$5:$P$117, 0))) -> 3.5284727 | I15: =IF(INDEX($O$5:$O$117, MATCH(G15, $P$5:$P$117, 0))-INDEX($O$5:$O$117, MATCH(F15, $P$5:$P$117, 0))>1,INDEX($O$5:$O$117, MATCH(G15, $P$5:$P$117, 0)),INDEX($O$5:$O$117, MATCH(G15+0.02, $P$5:$P$117, 0))) -> 5.5278927 | J15: =INDEX($N$5:$N$67, MATCH(H15, $O$5:$O$67, 0)) -> 9300.249 | K15: =INDEX($N$5:$N$67, MATCH(I15, $O$5:$O$67, 0)) -> 15006.95 | L15: =MAX(0, IFERROR((K15-J15)/(I15-H15), 0)) -> 2854.1782 | N15: =INDEX($B$4:$B$1298,MATCH(O15,$C$4:$C$1309,0),1) -> 9300.249 | O15: =LARGE($C$4:$C$1309,COUNTIF($C$4:$C$1309,">="&P15)) -> 3.5284727 | P15: 3.5
B16: 1233.213 | C16: 0.5652467 | F16: 3.5 | G16: 5 | H16: =IF(I16-INDEX($O$5:$O$117, MATCH(F16, $P$5:$P$117, 0))>1,INDEX($O$5:$O$117, MATCH(F16, $P$5:$P$117, 0)),INDEX($O$5:$O$117, MATCH(F16-0.02, $P$5:$P$117, 0))) -> 3.5284727 | I16: =IF(INDEX($O$5:$O$117, MATCH(G16, $P$5:$P$117, 0))-INDEX($O$5:$O$117, MATCH(F16, $P$5:$P$117, 0))>1,INDEX($O$5:$O$117, MATCH(G16, $P$5:$P$117, 0)),INDEX($O$5:$O$117, MATCH(G16+0.02, $P$5:$P$117, 0))) -> 5.0322567 | J16: =INDEX($N$5:$N$67, MATCH(H16, $O$5:$O$67, 0)) -> 9300.249 | K16: =INDEX($N$5:$N$67, MATCH(I16, $O$5:$O$67, 0)) -> 13592.11 | L16: =MAX(0, IFERROR((K16-J16)/(I16-H16), 0)) -> 2854.0409 | N16: =INDEX($B$4:$B$1298,MATCH(O16,$C$4:$C$1309,0),1) -> 9935.479 | O16: =LARGE($C$4:$C$1309,COUNTIF($C$4:$C$1309,">="&P16)) -> 3.7567447 | P16: 3.75
B17: 1317.376 | C17: 0.5988767 | F17: 4.5 | G17: 6 | H17: =IF(I17-INDEX($O$5:$O$117, MATCH(F17, $P$5:$P$117, 0))>1,INDEX($O$5:$O$117, MATCH(F17, $P$5:$P$117, 0)),INDEX($O$5:$O$117, MATCH(F17-0.02, $P$5:$P$117, 0))) -> 4.5380857 | I17: =IF(INDEX($O$5:$O$117, MATCH(G17, $P$5:$P$117, 0))-INDEX($O$5:$O$117, MATCH(F17, $P$5:$P$117, 0))>1,INDEX($O$5:$O$117, MATCH(G17, $P$5:$P$117, 0)),INDEX($O$5:$O$117, MATCH(G17+0.02, $P$5:$P$117, 0))) -> 6.0482487 | J17: =INDEX($N$5:$N$67, MATCH(H17, $O$5:$O$67, 0)) -> 12175.59 | K17: =INDEX($N$5:$N$67, MATCH(I17, $O$5:$O$67, 0)) -> 16484.25 | L17: =MAX(0, IFERROR((K17-J17)/(I17-H17), 0)) -> 2853.1092 | N17: =INDEX($B$4:$B$1298,MATCH(O17,$C$4:$C$1309,0),1) -> 10678.02 | O17: =LARGE($C$4:$C$1309,COUNTIF($C$4:$C$1309,">="&P17)) -> 4.0160217 | P17: 4
B18: 1482.336 | C18: 0.6640317 | F18: 3.25 | G18: 4.25 | H18: =IF(I18-INDEX($O$5:$O$117, MATCH(F18, $P$5:$P$117, 0))>1,INDEX($O$5:$O$117, MATCH(F18, $P$5:$P$117, 0)),INDEX($O$5:$O$117, MATCH(F18-0.02, $P$5:$P$117, 0))) -> 3.3009947 | I18: =IF(INDEX($O$5:$O$117, MATCH(G18, $P$5:$P$117, 0))-INDEX($O$5:$O$117, MATCH(F18, $P$5:$P$117, 0))>1,INDEX($O$5:$O$117, MATCH(G18, $P$5:$P$117, 0)),INDEX($O$5:$O$117, MATCH(G18+0.02, $P$5:$P$117, 0))) -> 4.3111577 | J18: =INDEX($N$5:$N$67, MATCH(H18, $O$5:$O$67, 0)) -> 8653.225 | K18: =INDEX($N$5:$N$67, MATCH(I18, $O$5:$O$67, 0)) -> 11532.33 | L18: =MAX(0, IFERROR((K18-J18)/(I18-H18), 0)) -> 2850.139 | N18: =INDEX($B$4:$B$1298,MATCH(O18,$C$4:$C$1309,0),1) -> 11532.33 | O18: =LARGE($C$4:$C$1309,COUNTIF($C$4:$C$1309,">="&P18)) -> 4.3111577 | P18: 4.25
B19: 1564.816 | C19: 0.6958317 | F19: 3.5 | G19: 4.5 | H19: =IF(I19-INDEX($O$5:$O$117, MATCH(F19, $P$5:$P$117, 0))>1,INDEX($O$5:$O$117, MATCH(F19, $P$5:$P$117, 0)),INDEX($O$5:$O$117, MATCH(F19-0.02, $P$5:$P$117, 0))) -> 3.5284727 | I19: =IF(INDEX($O$5:$O$117, MATCH(G19, $P$5:$P$117, 0))-INDEX($O$5:$O$117, MATCH(F19, $P$5:$P$117, 0))>1,INDEX($O$5:$O$117, MATCH(G19, $P$5:$P$117, 0)),INDEX($O$5:$O$117, MATCH(G19+0.02, $P$5:$P$117, 0))) -> 4.5380857 | J19: =INDEX($N$5:$N$67, MATCH(H19, $O$5:$O$67, 0)) -> 9300.249 | K19: =INDEX($N$5:$N$67, MATCH(I19, $O$5:$O$67, 0)) -> 12175.59 | L19: =MAX(0, IFERROR((K19-J19)/(I19-H19), 0)) -> 2847.9635 | N19: =INDEX($B$4:$B$1298,MATCH(O19,$C$4:$C$1309,0),1) -> 12175.59 | O19: =LARGE($C$4:$C$1309,COUNTIF($C$4:$C$1309,">="&P19)) -> 4.5380857 | P19: 4.5
B20: 1731.459 | C20: 0.7284237 | F20: 4.75 | G20: 6.25 | H20: =IF(I20-INDEX($O$5:$O$117, MATCH(F20, $P$5:$P$117, 0))>1,INDEX($O$5:$O$117, MATCH(F20, $P$5:$P$117, 0)),INDEX($O$5:$O$117, MATCH(F20-0.02, $P$5:$P$117, 0))) -> 4.7725217 | I20: =IF(INDEX($O$5:$O$117, MATCH(G20, $P$5:$P$117, 0))-INDEX($O$5:$O$117, MATCH(F20, $P$5:$P$117, 0))>1,INDEX($O$5:$O$117, MATCH(G20, $P$5:$P$117, 0)),INDEX($O$5:$O$117, MATCH(G20+0.02, $P$5:$P$117, 0))) -> 6.2759397 | J20: =INDEX($N$5:$N$67, MATCH(H20, $O$5:$O$67, 0)) -> 12842.48 | K20: =INDEX($N$5:$N$67, MATCH(I20, $O$5:$O$67, 0)) -> 17124.14 | L20: =MAX(0, IFERROR((K20-J20)/(I20-H20), 0)) -> 2847.9505 | N20: =INDEX($B$4:$B$1298,MATCH(O20,$C$4:$C$1309,0),1) -> 12842.48 | O20: =LARGE($C$4:$C$1309,COUNTIF($C$4:$C$1309,">="&P20)) -> 4.7725217 | P20: 4.75
... B75: 8558.867 | C75: 3.2365117 | F75: 6.25 | G75: 7.25 | H75: =IF(I75-INDEX($O$5:$O$117, MATCH(F75, $P$5:$P$117, 0))>1,INDEX($O$5:$O$117, MATCH(F75, $P$5:$P$117, 0)),INDEX($O$5:$O$117, MATCH(F75-0.02, $P$5:$P$117, 0))) -> 6.2759397 | I75: =IF(INDEX($O$5:$O$117, MATCH(G75, $P$5:$P$117, 0))-INDEX($O$5:$O$117, MATCH(F75, $P$5:$P$117, 0))>1,INDEX($O$5:$O$117, MATCH(G75, $P$5:$P$117, 0)),INDEX($O$5:$O$117, MATCH(G75+0.02, $P$5:$P$117, 0))) -> 7.3253177 | J75: =INDEX($N$5:$N$67, MATCH(H75, $O$5:$O$67, 0)) -> 17124.14 | K75: =INDEX($N$5:$N$67, MATCH(I75, $O$5:$O$67, 0)) -> #N/A | L75: =MAX(0, IFERROR((K75-J75)/(I75-H75), 0)) -> 0 | N75: =INDEX($B$4:$B$1298,MATCH(O75,$C$4:$C$1309,0),1) -> 13592.11 | O75: =LARGE($C$4:$C$1309,COUNTIF($C$4:$C$1309,">="&P75)) -> 5.0322567 | P75: 5.02
B76: 8653.225 | C76: 3.3009947 | F76: 6 | G76: 7 | H76: =IF(I76-INDEX($O$5:$O$117, MATCH(F76, $P$5:$P$117, 0))>1,INDEX($O$5:$O$117, MATCH(F76, $P$5:$P$117, 0)),INDEX($O$5:$O$117, MATCH(F76-0.02, $P$5:$P$117, 0))) -> 5.9828487 | I76: =IF(INDEX($O$5:$O$117, MATCH(G76, $P$5:$P$117, 0))-INDEX($O$5:$O$117, MATCH(F76, $P$5:$P$117, 0))>1,INDEX($O$5:$O$117, MATCH(G76, $P$5:$P$117, 0)),INDEX($O$5:$O$117, MATCH(G76+0.02, $P$5:$P$117, 0))) -> 7.0322567 | J76: =INDEX($N$5:$N$67, MATCH(H76, $O$5:$O$67, 0)) -> #N/A | K76: =INDEX($N$5:$N$67, MATCH(I76, $O$5:$O$67, 0)) -> 19271.72 | L76: =MAX(0, IFERROR((K76-J76)/(I76-H76), 0)) -> 0 | N76: =INDEX($B$4:$B$1298,MATCH(O76,$C$4:$C$1309,0),1) -> 14274.2 | O76: =LARGE($C$4:$C$1309,COUNTIF($C$4:$C$1309,">="&P76)) -> 5.2681577 | P76: =P68+1 -> 5.23
B77: 8744.213 | C77: 3.3337097 | F77: 8.5 | G77: 9.5 | H77: =IF(I77-INDEX($O$5:$O$117, MATCH(F77, $P$5:$P$117, 0))>1,INDEX($O$5:$O$117, MATCH(F77, $P$5:$P$117, 0)),INDEX($O$5:$O$117, MATCH(F77-0.02, $P$5:$P$117, 0))) -> 8.4974667 | I77: =IF(INDEX($O$5:$O$117, MATCH(G77, $P$5:$P$117, 0))-INDEX($O$5:$O$117, MATCH(F77, $P$5:$P$117, 0))>1,INDEX($O$5:$O$117, MATCH(G77, $P$5:$P$117, 0)),INDEX($O$5:$O$117, MATCH(G77+0.02, $P$5:$P$117, 0))) -> 9.5388157 | J77: =INDEX($N$5:$N$67, MATCH(H77, $O$5:$O$67, 0)) -> #N/A | K77: =INDEX($N$5:$N$67, MATCH(I77, $O$5:$O$67, 0)) -> #N/A | L77: =MAX(0, IFERROR((K77-J77)/(I77-H77), 0)) -> 0 | N77: =INDEX($B$4:$B$1298,MATCH(O77,$C$4:$C$1309,0),1) -> 14368.75 | O77: =LARGE($C$4:$C$1309,COUNTIF($C$4:$C$1309,">="&P77)) -> 5.2994077 | P77: =P69+1 -> 5.27
B78: 8929.558 | C78: 3.3992007 | F78: 4.75 | G78: 5.75 | H78: =IF(I78-INDEX($O$5:$O$117, MATCH(F78, $P$5:$P$117, 0))>1,INDEX($O$5:$O$117, MATCH(F78, $P$5:$P$117, 0)),INDEX($O$5:$O$117, MATCH(F78-0.02, $P$5:$P$117, 0))) -> 4.7725217 | I78: =IF(INDEX($O$5:$O$117, MATCH(G78, $P$5:$P$117, 0))-INDEX($O$5:$O$117, MATCH(F78, $P$5:$P$117, 0))>1,INDEX($O$5:$O$117, MATCH(G78, $P$5:$P$117, 0)),INDEX($O$5:$O$117, MATCH(G78+0.02, $P$5:$P$117, 0))) -> 5.8211057 | J78: =INDEX($N$5:$N$67, MATCH(H78, $O$5:$O$67, 0)) -> 12842.48 | K78: =INDEX($N$5:$N$67, MATCH(I78, $O$5:$O$67, 0)) -> #N/A | L78: =MAX(0, IFERROR((K78-J78)/(I78-H78), 0)) -> 0 | N78: =INDEX($B$4:$B$1298,MATCH(O78,$C$4:$C$1309,0),1) -> 14914.09 | O78: =LARGE($C$4:$C$1309,COUNTIF($C$4:$C$1309,">="&P78)) -> 5.4964907 | P78: =P70+1 -> 5.48
B79: 9022.231 | C79: 3.4309997 | F79: 6.75 | G79: 8.25 | H79: =IF(I79-INDEX($O$5:$O$117, MATCH(F79, $P$5:$P$117, 0))>1,INDEX($O$5:$O$117, MATCH(F79, $P$5:$P$117, 0)),INDEX($O$5:$O$117, MATCH(F79-0.02, $P$5:$P$117, 0))) -> 6.7666627 | I79: =IF(INDEX($O$5:$O$117, MATCH(G79, $P$5:$P$117, 0))-INDEX($O$5:$O$117, MATCH(F79, $P$5:$P$117, 0))>1,INDEX($O$5:$O$117, MATCH(G79, $P$5:$P$117, 0)),INDEX($O$5:$O$117, MATCH(G79+0.02, $P$5:$P$117, 0))) -> 8.2694087 | J79: =INDEX($N$5:$N$67, MATCH(H79, $O$5:$O$67, 0)) -> 18468.06 | K79: =INDEX($N$5:$N$67, MATCH(I79, $O$5:$O$67, 0)) -> 421.8788 | L79: =MAX(0, IFERROR((K79-J79)/(I79-H79), 0)) -> 0 | N79: =INDEX($B$4:$B$1298,MATCH(O79,$C$4:$C$1309,0),1) -> 15006.95 | O79: =LARGE($C$4:$C$1309,COUNTIF($C$4:$C$1309,">="&P79)) -> 5.5278927 | P79: =P71+1 -> 5.52
B80: 9207.577 | C80: 3.4640507 | F80: 7 | G80: 8.5 | H80: =IF(I80-INDEX($O$5:$O$117, MATCH(F80, $P$5:$P$117, 0))>1,INDEX($O$5:$O$117, MATCH(F80, $P$5:$P$117, 0)),INDEX($O$5:$O$117, MATCH(F80-0.02, $P$5:$P$117, 0))) -> 7.0322567 | I80: =IF(INDEX($O$5:$O$117, MATCH(G80, $P$5:$P$117, 0))-INDEX($O$5:$O$117, MATCH(F80, $P$5:$P$117, 0))>1,INDEX($O$5:$O$117, MATCH(G80, $P$5:$P$117, 0)),INDEX($O$5:$O$117, MATCH(G80+0.02, $P$5:$P$117, 0))) -> 8.5614927 | J80: =INDEX($N$5:$N$67, MATCH(H80, $O$5:$O$67, 0)) -> 19271.72 | K80: =INDEX($N$5:$N$67, MATCH(I80, $O$5:$O$67, 0)) -> 448.811 | L80: =MAX(0, IFERROR((K80-J80)/(I80-H80), 0)) -> 0 | N80: =INDEX($B$4:$B$1298,MATCH(O80,$C$4:$C$1309,0),1) -> 15668.78 | O80: =LARGE($C$4:$C$1309,COUNTIF($C$4:$C$1309,">="&P80)) -> 5.7560727 | P80: =P72+1 -> 5.73
B81: 9300.249 | C81: 3.5284727 | F81: 6.75 | G81: 8.75 | H81: =IF(I81-INDEX($O$5:$O$117, MATCH(F81, $P$5:$P$117, 0))>1,INDEX($O$5:$O$117, MATCH(F81, $P$5:$P$117, 0)),INDEX($O$5:$O$117, MATCH(F81-0.02, $P$5:$P$117, 0))) -> 6.7666627 | I81: =IF(INDEX($O$5:$O$117, MATCH(G81, $P$5:$P$117, 0))-INDEX($O$5:$O$117, MATCH(F81, $P$5:$P$117, 0))>1,INDEX($O$5:$O$117, MATCH(G81, $P$5:$P$117, 0)),INDEX($O$5:$O$117, MATCH(G81+0.02, $P$5:$P$117, 0))) -> 8.7897037 | J81: =INDEX($N$5:$N$67, MATCH(H81, $O$5:$O$67, 0)) -> 18468.06 | K81: =INDEX($N$5:$N$67, MATCH(I81, $O$5:$O$67, 0)) -> 465.6436 | L81: =MAX(0, IFERROR((K81-J81)/(I81-H81), 0)) -> 0 | N81: =INDEX($B$4:$B$1298,MATCH(O81,$C$4:$C$1309,0),1) -> 15840.99 | O81: =LARGE($C$4:$C$1309,COUNTIF($C$4:$C$1309,">="&P81)) -> 5.8211057 | P81: =P73+1 -> 5.77
B82: 9392.921 | C82: 3.5609127 | F82: 7.5 | G82: 8.5 | H82: =IF(I82-INDEX($O$5:$O$117, MATCH(F82, $P$5:$P$117, 0))>1,INDEX($O$5:$O$117, MATCH(F82, $P$5:$P$117, 0)),INDEX($O$5:$O$117, MATCH(F82-0.02, $P$5:$P$117, 0))) -> 7.5537107 | I82: =IF(INDEX($O$5:$O$117, MATCH(G82, $P$5:$P$117, 0))-INDEX($O$5:$O$117, MATCH(F82, $P$5:$P$117, 0))>1,INDEX($O$5:$O$117, MATCH(G82, $P$5:$P$117, 0)),INDEX($O$5:$O$117, MATCH(G82+0.02, $P$5:$P$117, 0))) -> 8.5614927 | J82: =INDEX($N$5:$N$67, MATCH(H82, $O$5:$O$67, 0)) -> 20523.15 | K82: =INDEX($N$5:$N$67, MATCH(I82, $O$5:$O$67, 0)) -> 448.811 | L82: =MAX(0, IFERROR((K82-J82)/(I82-H82), 0)) -> 0 | N82: =INDEX($B$4:$B$1298,MATCH(O82,$C$4:$C$1309,0),1) -> 16300.22 | O82: =LARGE($C$4:$C$1309,COUNTIF($C$4:$C$1309,">="&P82)) -> 5.9828487 | P82: =P74+1 -> 5.98
B83: 9576.583 | C83: 3.6278377 | F83: 7.25 | G83: 8.75 | H83: =IF(I83-INDEX($O$5:$O$117, MATCH(F83, $P$5:$P$117, 0))>1,INDEX($O$5:$O$117, MATCH(F83, $P$5:$P$117, 0)),INDEX($O$5:$O$117, MATCH(F83-0.02, $P$5:$P$117, 0))) -> 7.2589417 | I83: =IF(INDEX($O$5:$O$117, MATCH(G83, $P$5:$P$117, 0))-INDEX($O$5:$O$117, MATCH(F83, $P$5:$P$117, 0))>1,INDEX($O$5:$O$117, MATCH(G83, $P$5:$P$117, 0)),INDEX($O$5:$O$117, MATCH(G83+0.02, $P$5:$P$117, 0))) -> 8.7897037 | J83: =INDEX($N$5:$N$67, MATCH(H83, $O$5:$O$67, 0)) -> 19866.01 | K83: =INDEX($N$5:$N$67, MATCH(I83, $O$5:$O$67, 0)) -> 465.6436 | L83: =MAX(0, IFERROR((K83-J83)/(I83-H83), 0)) -> 0 | N83: =INDEX($B$4:$B$1298,MATCH(O83,$C$4:$C$1309,0),1) -> 16484.25 | O83: =LARGE($C$4:$C$1309,COUNTIF($C$4:$C$1309,">="&P83)) -> 6.0482487 | P83: =P75+1 -> 6.02
B84: 9655.776 | C84: 3.6592717 | F84: 7 | G84: 9 | H84: =IF(I84-INDEX($O$5:$O$117, MATCH(F84, $P$5:$P$117, 0))>1,INDEX($O$5:$O$117, MATCH(F84, $P$5:$P$117, 0)),INDEX($O$5:$O$117, MATCH(F84-0.02, $P$5:$P$117, 0))) -> 7.0322567 | I84: =IF(INDEX($O$5:$O$117, MATCH(G84, $P$5:$P$117, 0))-INDEX($O$5:$O$117, MATCH(F84, $P$5:$P$117, 0))>1,INDEX($O$5:$O$117, MATCH(G84, $P$5:$P$117, 0)),INDEX($O$5:$O$117, MATCH(G84+0.02, $P$5:$P$117, 0))) -> 9.0181887 | J84: =INDEX($N$5:$N$67, MATCH(H84, $O$5:$O$67, 0)) -> 19271.72 | K84: =INDEX($N$5:$N$67, MATCH(I84, $O$5:$O$67, 0)) -> 484.1596 | L84: =MAX(0, IFERROR((K84-J84)/(I84-H84), 0)) -> 0 | N84: =INDEX($B$4:$B$1298,MATCH(O84,$C$4:$C$1309,0),1) -> 17124.14 | O84: =LARGE($C$4:$C$1309,COUNTIF($C$4:$C$1309,">="&P84)) -> 6.2759397 | P84: =P76+1 -> 6.23
B85: 9842.807 | C85: 3.6917727 | F85: 7.75 | G85: 8.75 | H85: =IF(I85-INDEX($O$5:$O$117, MATCH(F85, $P$5:$P$117, 0))>1,INDEX($O$5:$O$117, MATCH(F85, $P$5:$P$117, 0)),INDEX($O$5:$O$117, MATCH(F85-0.02, $P$5:$P$117, 0))) -> 7.7821047 | I85: =IF(INDEX($O$5:$O$117, MATCH(G85, $P$5:$P$117, 0))-INDEX($O$5:$O$117, MATCH(F85, $P$5:$P$117, 0))>1,INDEX($O$5:$O$117, MATCH(G85, $P$5:$P$117, 0)),INDEX($O$5:$O$117, MATCH(G85+0.02, $P$5:$P$117, 0))) -> 8.7897037 | J85: =INDEX($N$5:$N$67, MATCH(H85, $O$5:$O$67, 0)) -> 21082.44 | K85: =INDEX($N$5:$N$67, MATCH(I85, $O$5:$O$67, 0)) -> 465.6436 | L85: =MAX(0, IFERROR((K85-J85)/(I85-H85), 0)) -> 0 | N85: =INDEX($B$4:$B$1298,MATCH(O85,$C$4:$C$1309,0),1) -> 17124.14 | O85: =LARGE($C$4:$C$1309,COUNTIF($C$4:$C$1309,">="&P85)) -> 6.2759397 | P85: =P77+1 -> 6.27
B86: 9935.479 | C86: 3.7567447 | F86: 7.5 | G86: 9 | H86: =IF(I86-INDEX($O$5:$O$117, MATCH(F86, $P$5:$P$117, 0))>1,INDEX($O$5:$O$117, MATCH(F86, $P$5:$P$117, 0)),INDEX($O$5:$O$117, MATCH(F86-0.02, $P$5:$P$117, 0))) -> 7.5537107 | I86: =IF(INDEX($O$5:$O$117, MATCH(G86, $P$5:$P$117, 0))-INDEX($O$5:$O$117, MATCH(F86, $P$5:$P$117, 0))>1,INDEX($O$5:$O$117, MATCH(G86, $P$5:$P$117, 0)),INDEX($O$5:$O$117, MATCH(G86+0.02, $P$5:$P$117, 0))) -> 9.0181887 | J86: =INDEX($N$5:$N$67, MATCH(H86, $O$5:$O$67, 0)) -> 20523.15 | K86: =INDEX($N$5:$N$67, MATCH(I86, $O$5:$O$67, 0)) -> 484.1596 | L86: =MAX(0, IFERROR((K86-J86)/(I86-H86), 0)) -> 0 | N86: =INDEX($B$4:$B$1298,MATCH(O86,$C$4:$C$1309,0),1) -> 17757.27 | O86: =LARGE($C$4:$C$1309,COUNTIF($C$4:$C$1309,">="&P86)) -> 6.5043637 | P86: =P78+1 -> 6.48
B87: 10028.15 | C87: 3.7893677 | F87: 7.25 | G87: 9.25 | H87: =IF(I87-INDEX($O$5:$O$117, MATCH(F87, $P$5:$P$117, 0))>1,INDEX($O$5:$O$117, MATCH(F87, $P$5:$P$117, 0)),INDEX($O$5:$O$117, MATCH(F87-0.02, $P$5:$P$117, 0))) -> 7.2589417 | I87: =IF(INDEX($O$5:$O$117, MATCH(G87, $P$5:$P$117, 0))-INDEX($O$5:$O$117, MATCH(F87, $P$5:$P$117, 0))>1,INDEX($O$5:$O$117, MATCH(G87, $P$5:$P$117, 0)),INDEX($O$5:$O$117, MATCH(G87+0.02, $P$5:$P$117, 0))) -> 9.2768557 | J87: =INDEX($N$5:$N$67, MATCH(H87, $O$5:$O$67, 0)) -> 19866.01 | K87: =INDEX($N$5:$N$67, MATCH(I87, $O$5:$O$67, 0)) -> 502.6755 | L87: =MAX(0, IFERROR((K87-J87)/(I87-H87), 0)) -> 0 | N87: =INDEX($B$4:$B$1298,MATCH(O87,$C$4:$C$1309,0),1) -> 17845.06 | O87: =LARGE($C$4:$C$1309,COUNTIF($C$4:$C$1309,">="&P87)) -> 6.5370487 | P87: =P79+1 -> 6.52
... B98: 11532.33 | C98: 4.3111577 | F98: 8 | G98: 9 | H98: =IF(I98-INDEX($O$5:$O$117, MATCH(F98, $P$5:$P$117, 0))>1,INDEX($O$5:$O$117, MATCH(F98, $P$5:$P$117, 0)),INDEX($O$5:$O$117, MATCH(F98-0.02, $P$5:$P$117, 0))) -> 8.0078737 | I98: =IF(INDEX($O$5:$O$117, MATCH(G98, $P$5:$P$117, 0))-INDEX($O$5:$O$117, MATCH(F98, $P$5:$P$117, 0))>1,INDEX($O$5:$O$117, MATCH(G98, $P$5:$P$117, 0)),INDEX($O$5:$O$117, MATCH(G98+0.02, $P$5:$P$117, 0))) -> 9.0181887 | J98: =INDEX($N$5:$N$67, MATCH(H98, $O$5:$O$67, 0)) -> 18327.93 | K98: =INDEX($N$5:$N$67, MATCH(I98, $O$5:$O$67, 0)) -> 484.1596 | L98: =MAX(0, IFERROR((K98-J98)/(I98-H98), 0)) -> 0 | N98: =INDEX($B$4:$B$1298,MATCH(O98,$C$4:$C$1309,0),1) -> 18327.93 | O98: =LARGE($C$4:$C$1309,COUNTIF($C$4:$C$1309,">="&P98)) -> 8.0078737 | P98: =P90+1 -> 7.98
B99: 11613.37 | C99: 4.3428957 | N99: =INDEX($B$4:$B$1298,MATCH(O99,$C$4:$C$1309,0),1) -> 13739 | O99: =LARGE($C$4:$C$1309,COUNTIF($C$4:$C$1309,">="&P99)) -> 8.0415647 | P99: =P91+1 -> 8.02
B100: 11800.77 | C100: 4.3754277 | N100: =INDEX($B$4:$B$1298,MATCH(O100,$C$4:$C$1309,0),1) -> 418.5122 | O100: =LARGE($C$4:$C$1309,COUNTIF($C$4:$C$1309,">="&P100)) -> 8.2367247 | P100: =P92+1 -> 8.23
B101: 11895.32 | C101: 4.4399107 | N101: =INDEX($B$4:$B$1298,MATCH(O101,$C$4:$C$1309,0),1) -> 428.6118 | O101: =LARGE($C$4:$C$1309,COUNTIF($C$4:$C$1309,">="&P101)) -> 8.3341677 | P101: =P93+1 -> 8.27
B102: 11988.18 | C102: 4.4745487 | N102: =INDEX($B$4:$B$1298,MATCH(O102,$C$4:$C$1309,0),1) -> 442.0779 | O102: =LARGE($C$4:$C$1309,COUNTIF($C$4:$C$1309,">="&P102)) -> 8.4974667 | P102: =P94+1 -> 8.48
B103: 12175.59 | C103: 4.5380857 | N103: =INDEX($B$4:$B$1298,MATCH(O103,$C$4:$C$1309,0),1) -> 448.811 | O103: =LARGE($C$4:$C$1309,COUNTIF($C$4:$C$1309,">="&P103)) -> 8.5614927 | P103: =P95+1 -> 8.52
B104: 12268.45 | C104: 4.5705257 | N104: =INDEX($B$4:$B$1298,MATCH(O104,$C$4:$C$1309,0),1) -> 465.6436 | O104: =LARGE($C$4:$C$1309,COUNTIF($C$4:$C$1309,">="&P104)) -> 8.7897037 | P104: =P96+1 -> 8.73
B105: 12455.85 | C105: 4.6022037 | N105: =INDEX($B$4:$B$1298,MATCH(O105,$C$4:$C$1309,0),1) -> 465.6436 | O105: =LARGE($C$4:$C$1309,COUNTIF($C$4:$C$1309,">="&P105)) -> 8.7897037 | P105: =P97+1 -> 8.77
B106: 12562.22 | C106: 4.6748347 | N106: =INDEX($B$4:$B$1298,MATCH(O106,$C$4:$C$1309,0),1) -> 484.1596 | O106: =LARGE($C$4:$C$1309,COUNTIF($C$4:$C$1309,">="&P106)) -> 9.0181887 | P106: =P98+1 -> 8.98
...

Sheet Base de Datos Probetas
B2: Gradiente y X y Y ideales ocultos para no ocupar espacio + Datos extra
B4: COEFICIENTES DE SEGURIDAD
B5: Probeta | C5: Core | D5: Espesor Core [mm] | E5: Prueba | F5: Peso Real Probeta [g] | G5: Laminado | H5: x1 | I5: x2 | J5: y1 | K5: y2 | L5: Ymax [N] | M5: Gradiente | N5: Higher Peak [N] | O5: Lower Peak [N] | P5: FBH [P. Shear] | Q5: FHB [EI] | R5: FBHS [EI] | S5: SISv [EI] | T5: SISh [EI] | U5: MHBS [EI] | V5: SHB [EI] | W5: Comentarios
B6: 000-Prueba | E6: 3PB | F6: x | G6: x
B7: 2026-P01-01 | C7: HC | D7: 20 | E7: 3PB | F7: 1350 | G7: [+-45/0/+-45/+-90/+-45/+-90] S. | H7: 2.015442 | I7: 3.024994 | J7: 6791.268 | K7: 11403.96 | L7: 17831.5 | M7: =IFERROR((K7-J7)/(I7-H7),"-") -> 4569.0484 | N7: - | O7: - | P7: N/A | Q7: 1.586 | R7: 1.862 | S7: 1.171 | T7: 0.802 | U7: 2.051 | V7: 0.967 | W7: Hechas con eje debil // RC 416 + UD300
B8: 2026-P01-02 | C8: HC | D8: 20 | E8: 3PB | F8: 1318 | G8: [+-45/0/+-45/+-90/0/+-45] S. | H8: 2.48764 | I8: 3.528991 | J8: 8782.853 | K8: 13646.07 | L8: 18447.73 | M8: =IFERROR((K8-J8)/(I8-H8),"-") -> 4670.1035 | N8: - | O8: - | P8: N/A | Q8: 1.621 | R8: 1.903 | S8: 1.196 | T8: 0.819 | U8: 2.097 | V8: 0.989 | W8: Hechas con eje debil // RC 416 + UD300
B9: 2026-P01-03 | C9: HC | D9: 20 | E9: 3PB | F9: 1779 | G9: [+-45/0/+-45/+-90/+-45/+-90/+-45/+-90] S. | H9: 2.025207 | I9: 3.033905 | J9: 6890.671 | K9: 12557.1 | L9: 22630.17 | M9: =IFERROR((K9-J9)/(I9-H9),"-") -> 5617.5674 | N9: - | O9: - | P9: N/A | Q9: 1.95 | R9: 2.289 | S9: 1.439 | T9: 0.986 | U9: 2.522 | V9: 1.189 | W9: Hechas con eje debil // RC 416 + UD300
B10: 2026-P02-01 | C10: HC | D10: 20 | E10: 3PB | F10: 1162 | G10: [+-45/0/+-45/0/+-45] S. | H10: 2.737915 | I10: 3.786896 | J10: 9434.913 | K10: 14291 | L10: 24654.41 | M10: =IFERROR((K10-J10)/(I10-H10),"-") -> 4629.3374 | N10: - | O10: - | P10: N/A | Q10: 1.607 | R10: 1.886 | S10: 1.186 | T10: 0.812 | U10: 2.078 | V10: 0.98 | W10: RC 416 + UD300
B11: 2026-P02-01 v2 | C11: HC | D11: 20 | E11: 3PB | F11: 1162 | G11: [+-45/0/+-45/0/+-45] S. | H11: 2.737915 | I11: 3.786896 | J11: 9906.6586 | K11: 15005.55 | L11: 25887.13 | M11: =IFERROR((K11-J11)/(I11-H11),"-") -> 4860.8043 | Q11: 1.687 | R11: 1.98 | S11: 1.245 | T11: 0.853 | U11: 2.182 | V11: 1.029 | W11: 2026-P02-01 x1,05
B12: 2026-P02-02 | C12: HC | D12: 20 | E12: 3PB | F12: 1073 | G12: [+-45/0/+-45/+-90] S. | H12: 4.014618 | I12: 5.513275 | J12: 12604.12 | K12: 18785.16 | L12: 21088.96 | M12: =IFERROR((K12-J12)/(I12-H12),"-") -> 4124.386 | N12: - | O12: - | P12: N/A | Q12: 1.431 | R12: 1.68 | S12: 1.057 | T12: 0.724 | U12: 1.852 | V12: 0.873 | W12: No cumple Energia absorbida para el SISv // RC 416 + UD300
B13: 2026-P02-03 | C13: HC | D13: 20 | E13: 3PB | F13: 868 | G13: [+-90/0/+-45] S. | H13: 2.025177 | I13: 3.509643 | J13: 6160.313 | K13: 11511.62 | L13: 20742.53 | M13: =IFERROR((K13-J13)/(I13-H13),"-") -> 3604.87 | N13: - | O13: - | P13: N/A | Q13: 1.251 | R13: 1.469 | S13: 0.924 | T13: 0.632 | U13: 1.618 | V13: 0.763 | W13: No cumple Energia absorbida para el SISv // RC 416 + UD300
B14: 2026-P02-S01 | C14: Balsa | D14: 9.5 | E14: Shear | F14: 95 g | G14: [+-45/0/+-45/+-90/+-45/+-90] S. | H14: - | I14: - | J14: - | K14: - | L14: - | M14: =IFERROR((K14-J14)/(I14-H14),"-") -> - | N14: 24302.97 | O14: 24091.76 | P14: 0.755 | Q14: N/A | R14: N/A | S14: N/A | T14: N/A | U14: N/A | V14: N/A | W14: RC 416 + UD300
B15: 2026-P02-S02 | C15: Balsa | D15: 9.5 | E15: Shear | F15: 77 g | G15: [+-45/0/+-45/+-90/+-45] S. | H15: - | I15: - | J15: - | K15: - | L15: - | M15: =IFERROR((K15-J15)/(I15-H15),"-") -> - | N15: 25250.84 | O15: 20445.32 | P15: 0.641 | Q15: N/A | R15: N/A | S15: N/A | T15: N/A | U15: N/A | V15: N/A | W15: RC 416 + UD300
B16: 2026-P03-01 | C16: Balsa | D16: 9.5 | E16: 3PB | F16: 1813 | G16: [+-45/0/+-45/+-90/0/+-45/+-90/+-45] S. | H16: 1.993316 | I16: 3.045135 | J16: 3037.751 | K16: 5017.271 | L16: 7455.285 | M16: =IFERROR((K16-J16)/(I16-H16),"-") -> 1881.9968 | N16: - | O16: - | P16: N/A | Q16: 0.653 | R16: 0.767 | S16: 0.482 | T16: 0.33 | U16: 0.845 | V16: 0.398 | W16: RC 416 + UD300
B17: 2026-P03-H01 | C17: HC | D17: 20 | E17: Harness | F17: - | G17: [+-45/0/+-45/0/+-45] S. | H17: - | I17: - | J17: - | K17: - | L17: - | M17: =IFERROR((K17-J17)/(I17-H17),"-") -> - | N17: - | O17: - | P17: N/A | Q17: N/A | R17: N/A | S17: N/A | T17: N/A | U17: N/A | V17: N/A | W17: RC 416 + UD300 / Laminada: 320x320 Recanteada: 101*300 x1,35
B18: 2026-P03-L01 | C18: HC-HP | D18: 20 | E18: Lap Belt Perp. | F18: - | G18: [+-45/0/+-45/0/+-45] S. | H18: - | I18: - | J18: - | K18: - | L18: - | M18: =IFERROR((K18-J18)/(I18-H18),"-") -> - | N18: - | O18: - | P18: N/A | Q18: N/A | R18: N/A | S18: N/A | T18: N/A | U18: N/A | V18: N/A | W18: RC 416 + UD300 / Lleva Hardpoint / Laminada: 320x320 Recanteada: 300x300
B19: 2026-P03-L02 | C19: HC-HP | D19: 20 | E19: Lap Belt Parallel | F19: - | G19: [+-45/0/+-45/0/+-45] S. | H19: - | I19: - | J19: - | K19: - | L19: - | M19: =IFERROR((K19-J19)/(I19-H19),"-") -> - | N19: - | O19: - | P19: N/A | Q19: N/A | R19: N/A | S19: N/A | T19: N/A | U19: N/A | V19: N/A | W19: RC 416 + UD300 / Laminada: 320x320 Recanteada: 300*300 x1,1
B20: 2026-P03-S01 | C20: Balsa | D20: 9.5 | E20: 3PB | F20: 128 g | G20: [+-45/0/+-45/+-90/0/+-45/+-90/+-45] S. | H20: - | I20: - | J20: - | K20: - | L20: - | M20: =IFERROR((K20-J20)/(I20-H20),"-") -> - | N20: 47168.1 | O20: 44568.2 | P20: 1.397 | Q20: N/A | R20: N/A | S20: N/A | T20: N/A | U20: N/A | V20: N/A | W20: RC 416 + UD300
B21: 2026-P03-S02 | C21: HC | D21: 20 | E21: Shear | F21: 83 g | G21: [+-45/0/+-45/0/+-45] S. | H21: - | I21: - | J21: - | K21: - | L21: - | M21: =IFERROR((K21-J21)/(I21-H21),"-") -> - | N21: 20607.64 | O21: 15994.64 | P21: 0.502 | Q21: N/A | R21: N/A | S21: N/A | T21: N/A | U21: N/A | V21: N/A | W21: RC 416 + UD300
B22: 2026-P03-S03 | C22: HC | D22: 20 | E22: Shear | F22: 59 g | G22: [+-90/0/+-45] S. | H22: - | I22: - | J22: - | K22: - | L22: - | M22: =IFERROR((K22-J22)/(I22-H22),"-") -> - | N22: 13286.47 | O22: 12079.3 | P22: 0.379 | Q22: N/A | R22: N/A | S22: N/A | T22: N/A | U22: N/A | V22: N/A | W22: RC 416 + UD300
B23: 2026-P04-01 | C23: Balsa | D23: 12.7 | E23: 3PB | G23: [+-45/0/+-45/+-90/0/+-45] S. | H23: 3.7567447 | I23: 5.2681577 | J23: 9935.479 | K23: 14274.2 | L23: 21521.77 | M23: =IFERROR((K23-J23)/(I23-H23),"-") -> 2870.6389 | N23: - | O23: - | P23: N/A | Q23: 0.996 | R23: 1.17 | S23: 0.735 | T23: 0.504 | U23: 1.289 | V23: 0.608 | W23: RC 416 + UD300
B24: 2026-P04-S01 | C24: Balsa | D24: 12.7 | E24: Shear | G24: [+-45/0/+-45/+-90/0/+-45] S. | H24: - | I24: - | J24: - | K24: - | L24: - | M24: =IFERROR((K24-J24)/(I24-H24),"-") -> - | N24: 33002.92 | O24: 31187.93 | Q24: N/A | R24: N/A | S24: N/A | T24: N/A | U24: N/A | V24: N/A | W24: Testeada, picos 30kN aprox. Poxolen la lio y no metio en el Pen // MATLAB
M25: =IFERROR((K25-J25)/(I25-H25),"-") -> -
M26: =IFERROR((K26-J26)/(I26-H26),"-") -> -
M27: =IFERROR((K27-J27)/(I27-H27),"-") -> -
M28: =IFERROR((K28-J28)/(I28-H28),"-") -> -
M29: =IFERROR((K29-J29)/(I29-H29),"-") -> -
M30: =IFERROR((K30-J30)/(I30-H30),"-") -> -
M31: =IFERROR((K31-J31)/(I31-H31),"-") -> -
M32: =IFERROR((K32-J32)/(I32-H32),"-") -> -
M33: =IFERROR((K33-J33)/(I33-H33),"-") -> -
M34: =IFERROR((K34-J34)/(I34-H34),"-") -> -
M35: =IFERROR((K35-J35)/(I35-H35),"-") -> -
M36: =IFERROR((K36-J36)/(I36-H36),"-") -> -
... M500: =IFERROR((K500-J500)/(I500-H500),"-") -> -

Sheet Calculadora SES
B2: SOLO TOCAR LO QUE TENGA ESTE FONDO | I2: SOLO TOCAR LO QUE TENGA ESTE FONDO | O2: SOLO TOCAR LO QUE TENGA ESTE FONDO | S2: SOLO TOCAR LO QUE TENGA ESTE FONDO
B4: PROPIEDADES LAMINADO | I4: CALCULADORA 3PB SES | O4: CALCULADORA SHEAR SES | S4: DATOS EXTRAS SES | X4: OUTER | Y4: INNER | AA4: Second Moment of Area [mm^4] | AB4: =(X27*(((D14+SUM(D6:D13)*2)^3)-(D17^3))/12) -> 72859.423
B5: Nº Capa | C5: Orientación [º] | D5: Espesor [mm] | E5: Peso fibras [g] | F5: Peso [g] | G5: Peso fibras a 0º | W5: b | X5: =L7 -> 248.17 | Y5: =L7 -> 248.17 | AA5: σ UTS [pa] | AB5: =(L11*AB24*0.5*(D17+2*D18)/(4*AB4))*1000000 -> 3.182862e+08
B6: Capa 8 | C6: {=_xlfn.LET( _xlpm.texto_laminado, VLOOKUP($J$7, 'Base de Datos Probetas'!$B$6:$G$1000, 6, FALSE), _xlpm.limpio, SUBSTITUTE(SUBSTITUTE(SUBSTITUTE(_xlpm.texto_laminado, "[", ""), "]", ""), " S.", ""), _xlpm.capas, _xlfn.TEXTSPLIT(_xlpm.limpio, "/"), _xlpm.num_capas, COUNTA(_xlpm.capas), _xlpm.indice_capa, _xlpm.num_capas - (13 - ROW()), IF(OR(_xlpm.indice_capa < 1, _xlpm.indice_capa > _xlpm.num_capas), "-", _xlfn.LET( _xlpm.val, INDEX(_xlpm.capas, 1, _xlpm.indice_capa), IF(_xlpm.val="+-45", "RC +-45º", IF(_xlpm.val="+-90", "RC +-90º", IF(_xlpm.val="0", "UD 0º", _xlpm.val))) ) ) )} -> - | D6: {=_xlfn.IFS(ISNUMBER(SEARCH("RC",C6)),$X$35,ISNUMBER(SEARCH("XC",C6)),$X$37,ISNUMBER(SEARCH("UD",C6)),$X$36,ISNUMBER(SEARCH("-",C6)),0)} -> 0 | E6: {=_xlfn.IFS(ISNUMBER(SEARCH("RC",C6)),$X$26*0.001*$X$27*0.001*$X$30,ISNUMBER(SEARCH("XC",C6)),$X$26*0.001*$X$27*0.001*$X$32,ISNUMBER(SEARCH("UD",C6)),$X$26*0.001*$X$27*0.001*$X$31,ISNUMBER(SEARCH("-",C6)),0)} -> 0 | F6: {=_xlfn.IFS(ISNUMBER(SEARCH("RC",C6)),E6/(1-$Z$35),ISNUMBER(SEARCH("UD",C6)),E6/(1-$Z$36),ISNUMBER(SEARCH("UD",C6)),E6/(1-$Z$37),ISNUMBER(SEARCH("-",C6)),0)} -> 0 | G6: {=_xlfn.IFS( C6="-", 0, ISNUMBER(SEARCH($W$16,C6)), E6*0, ISNUMBER(SEARCH($W$17,C6)), E6*0.5, ISNUMBER(SEARCH($W$23,C6)), E6*0.5, ISNUMBER(SEARCH($W$22,C6)), E6*0, ISNUMBER(SEARCH($W$18,C6)), E6*1, OR(ISNUMBER(SEARCH($W$19,C6)),ISNUMBER(SEARCH($W$20,C6)),ISNUMBER(SEARCH($W$21,C6))), E6*0, TRUE, 0)} -> 0 | I6: PANEL | J6: PROBETA | L6: PANNEL HEIGHT [mm] | O6: Lower Peak [N] | P6: =IF(VLOOKUP(J7,'Base de Datos Probetas'!B6:O1000,14,FALSE)=0,"N/A",VLOOKUP(J7,'Base de Datos Probetas'!B6:O1000,14,FALSE)) -> - | T6: Yield Tensile Strength [N] | W6: h | X6: =D18 -> 1.18 | Y6: =D18 -> 1.18
B7: Capa 7 | C7: {=_xlfn.LET( _xlpm.texto_laminado, VLOOKUP($J$7, 'Base de Datos Probetas'!$B$6:$G$1000, 6, FALSE), _xlpm.limpio, SUBSTITUTE(SUBSTITUTE(SUBSTITUTE(_xlpm.texto_laminado, "[", ""), "]", ""), " S.", ""), _xlpm.capas, _xlfn.TEXTSPLIT(_xlpm.limpio, "/"), _xlpm.num_capas, COUNTA(_xlpm.capas), _xlpm.indice_capa, _xlpm.num_capas - (13 - ROW()), IF(OR(_xlpm.indice_capa < 1, _xlpm.indice_capa > _xlpm.num_capas), "-", _xlfn.LET( _xlpm.val, INDEX(_xlpm.capas, 1, _xlpm.indice_capa), IF(_xlpm.val="+-45", "RC +-45º", IF(_xlpm.val="+-90", "RC +-90º", IF(_xlpm.val="0", "UD 0º", _xlpm.val))) ) ) )} -> - | D7: {=_xlfn.IFS(ISNUMBER(SEARCH("RC",C7)),$X$35,ISNUMBER(SEARCH("XC",C7)),$X$37,ISNUMBER(SEARCH("UD",C7)),$X$36,ISNUMBER(SEARCH("-",C7)),0)} -> 0 | E7: {=_xlfn.IFS(ISNUMBER(SEARCH("RC",C7)),$X$26*0.001*$X$27*0.001*$X$30,ISNUMBER(SEARCH("XC",C7)),$X$26*0.001*$X$27*0.001*$X$32,ISNUMBER(SEARCH("UD",C7)),$X$26*0.001*$X$27*0.001*$X$31,ISNUMBER(SEARCH("-",C7)),0)} -> 0 | F7: {=_xlfn.IFS(ISNUMBER(SEARCH("RC",C7)),E7/(1-$Z$35),ISNUMBER(SEARCH("UD",C7)),E7/(1-$Z$36),ISNUMBER(SEARCH("UD",C7)),E7/(1-$Z$37),ISNUMBER(SEARCH("-",C7)),0)} -> 0 | G7: {=_xlfn.IFS( C7="-", 0, ISNUMBER(SEARCH($W$16,C7)), E7*0, ISNUMBER(SEARCH($W$17,C7)), E7*0.5, ISNUMBER(SEARCH($W$23,C7)), E7*0.5, ISNUMBER(SEARCH($W$22,C7)), E7*0, ISNUMBER(SEARCH($W$18,C7)), E7*1, OR(ISNUMBER(SEARCH($W$19,C7)),ISNUMBER(SEARCH($W$20,C7)),ISNUMBER(SEARCH($W$21,C7))), E7*0, TRUE, 0)} -> 0 | I7: MHBS | J7: 2026-P02-03 | L7: {=_xlfn.IFS( I7="FBH", X44, I7="FHB", X45, I7="FBHS", X46, I7="SHB", X50, I7="MHBS", X49, I7="SISv", X47, I7="SISh", X48)} -> 248.17 | O7: Higher Peak [N] | P7: =IF(VLOOKUP(J7,'Base de Datos Probetas'!B6:O1000,13,FALSE)=0,"N/A",VLOOKUP(J7,'Base de Datos Probetas'!B6:O1000,13,FALSE)) -> - | S7: Probeta | T7: =AB27*AB5/1000000 -> 186414.24
B8: Capa 6 | C8: {=_xlfn.LET( _xlpm.texto_laminado, VLOOKUP($J$7, 'Base de Datos Probetas'!$B$6:$G$1000, 6, FALSE), _xlpm.limpio, SUBSTITUTE(SUBSTITUTE(SUBSTITUTE(_xlpm.texto_laminado, "[", ""), "]", ""), " S.", ""), _xlpm.capas, _xlfn.TEXTSPLIT(_xlpm.limpio, "/"), _xlpm.num_capas, COUNTA(_xlpm.capas), _xlpm.indice_capa, _xlpm.num_capas - (13 - ROW()), IF(OR(_xlpm.indice_capa < 1, _xlpm.indice_capa > _xlpm.num_capas), "-", _xlfn.LET( _xlpm.val, INDEX(_xlpm.capas, 1, _xlpm.indice_capa), IF(_xlpm.val="+-45", "RC +-45º", IF(_xlpm.val="+-90", "RC +-90º", IF(_xlpm.val="0", "UD 0º", _xlpm.val))) ) ) )} -> - | D8: {=_xlfn.IFS(ISNUMBER(SEARCH("RC",C8)),$X$35,ISNUMBER(SEARCH("XC",C8)),$X$37,ISNUMBER(SEARCH("UD",C8)),$X$36,ISNUMBER(SEARCH("-",C8)),0)} -> 0 | E8: {=_xlfn.IFS(ISNUMBER(SEARCH("RC",C8)),$X$26*0.001*$X$27*0.001*$X$30,ISNUMBER(SEARCH("XC",C8)),$X$26*0.001*$X$27*0.001*$X$32,ISNUMBER(SEARCH("UD",C8)),$X$26*0.001*$X$27*0.001*$X$31,ISNUMBER(SEARCH("-",C8)),0)} -> 0 | F8: {=_xlfn.IFS(ISNUMBER(SEARCH("RC",C8)),E8/(1-$Z$35),ISNUMBER(SEARCH("UD",C8)),E8/(1-$Z$36),ISNUMBER(SEARCH("UD",C8)),E8/(1-$Z$37),ISNUMBER(SEARCH("-",C8)),0)} -> 0 | G8: {=_xlfn.IFS( C8="-", 0, ISNUMBER(SEARCH($W$16,C8)), E8*0, ISNUMBER(SEARCH($W$17,C8)), E8*0.5, ISNUMBER(SEARCH($W$23,C8)), E8*0.5, ISNUMBER(SEARCH($W$22,C8)), E8*0, ISNUMBER(SEARCH($W$18,C8)), E8*1, OR(ISNUMBER(SEARCH($W$19,C8)),ISNUMBER(SEARCH($W$20,C8)),ISNUMBER(SEARCH($W$21,C8))), E8*0, TRUE, 0)} -> 0 | O8: σ shear [Mpa] | P8: {=IFERROR(_xlfn.IFS( I7="FBH", P6/(PI()*25*D18), I7="FHB", P6/(PI()*25*D18), I7="FBHS", P7/(PI()*25*D18), I7="SHB", P6/(PI()*25*D18), I7="MHBS", P6/(PI()*25*D18), I7="SISv", P7/(PI()*25*D18), I7="SISh", P6/(PI()*25*D18)),"-")} -> - | S8: Objetivo | T8: {=_xlfn.IFS( I7="FBH", 73000, I7="FHB", 36500, I7="FBHS", 83500, I7="SHB", 52900, I7="MHBS", 55700, I7="SISv", 109000, I7="SISh", 109000)} -> 55700 | W8: A1 | X8: =X5*X6 -> 292.8406 | Y8: I1 | Z8: =(X5*X6^3)/12 -> 33.979271
B9: Capa 5 | C9: {=_xlfn.LET( _xlpm.texto_laminado, VLOOKUP($J$7, 'Base de Datos Probetas'!$B$6:$G$1000, 6, FALSE), _xlpm.limpio, SUBSTITUTE(SUBSTITUTE(SUBSTITUTE(_xlpm.texto_laminado, "[", ""), "]", ""), " S.", ""), _xlpm.capas, _xlfn.TEXTSPLIT(_xlpm.limpio, "/"), _xlpm.num_capas, COUNTA(_xlpm.capas), _xlpm.indice_capa, _xlpm.num_capas - (13 - ROW()), IF(OR(_xlpm.indice_capa < 1, _xlpm.indice_capa > _xlpm.num_capas), "-", _xlfn.LET( _xlpm.val, INDEX(_xlpm.capas, 1, _xlpm.indice_capa), IF(_xlpm.val="+-45", "RC +-45º", IF(_xlpm.val="+-90", "RC +-90º", IF(_xlpm.val="0", "UD 0º", _xlpm.val))) ) ) )} -> - | D9: {=_xlfn.IFS(ISNUMBER(SEARCH("RC",C9)),$X$35,ISNUMBER(SEARCH("XC",C9)),$X$37,ISNUMBER(SEARCH("UD",C9)),$X$36,ISNUMBER(SEARCH("-",C9)),0)} -> 0 | E9: {=_xlfn.IFS(ISNUMBER(SEARCH("RC",C9)),$X$26*0.001*$X$27*0.001*$X$30,ISNUMBER(SEARCH("XC",C9)),$X$26*0.001*$X$27*0.001*$X$32,ISNUMBER(SEARCH("UD",C9)),$X$26*0.001*$X$27*0.001*$X$31,ISNUMBER(SEARCH("-",C9)),0)} -> 0 | F9: {=_xlfn.IFS(ISNUMBER(SEARCH("RC",C9)),E9/(1-$Z$35),ISNUMBER(SEARCH("UD",C9)),E9/(1-$Z$36),ISNUMBER(SEARCH("UD",C9)),E9/(1-$Z$37),ISNUMBER(SEARCH("-",C9)),0)} -> 0 | G9: {=_xlfn.IFS( C9="-", 0, ISNUMBER(SEARCH($W$16,C9)), E9*0, ISNUMBER(SEARCH($W$17,C9)), E9*0.5, ISNUMBER(SEARCH($W$23,C9)), E9*0.5, ISNUMBER(SEARCH($W$22,C9)), E9*0, ISNUMBER(SEARCH($W$18,C9)), E9*1, OR(ISNUMBER(SEARCH($W$19,C9)),ISNUMBER(SEARCH($W$20,C9)),ISNUMBER(SEARCH($W$21,C9))), E9*0, TRUE, 0)} -> 0 | I9: x1 [mm] | J9: =IF(VLOOKUP(J7,'Base de Datos Probetas'!B6:M1000,7,FALSE)=0,"-",VLOOKUP(J7,'Base de Datos Probetas'!B6:M1000,7,FALSE)) -> 2.025177 | K9: y1 [N] | L9: =IF(VLOOKUP(J7,'Base de Datos Probetas'!B6:M1000,9,FALSE)=0,"-",VLOOKUP(J7,'Base de Datos Probetas'!B6:M1000,9,FALSE)) -> 6160.313 | S9: Coeficiente de Seguridad | T9: =IF(OR(I7="SISv",I7="SISh"),"NA",T7/T8) -> 3.3467548 | W9: A2 | X9: =Y5*Y6 -> 292.8406 | Y9: I2 | Z9: =(Y5*Y6^3)/12 -> 33.979271
B10: Capa 4 | C10: {=_xlfn.LET( _xlpm.texto_laminado, VLOOKUP($J$7, 'Base de Datos Probetas'!$B$6:$G$1000, 6, FALSE), _xlpm.limpio, SUBSTITUTE(SUBSTITUTE(SUBSTITUTE(_xlpm.texto_laminado, "[", ""), "]", ""), " S.", ""), _xlpm.capas, _xlfn.TEXTSPLIT(_xlpm.limpio, "/"), _xlpm.num_capas, COUNTA(_xlpm.capas), _xlpm.indice_capa, _xlpm.num_capas - (13 - ROW()), IF(OR(_xlpm.indice_capa < 1, _xlpm.indice_capa > _xlpm.num_capas), "-", _xlfn.LET( _xlpm.val, INDEX(_xlpm.capas, 1, _xlpm.indice_capa), IF(_xlpm.val="+-45", "RC +-45º", IF(_xlpm.val="+-90", "RC +-90º", IF(_xlpm.val="0", "UD 0º", _xlpm.val))) ) ) )} -> - | D10: {=_xlfn.IFS(ISNUMBER(SEARCH("RC",C10)),$X$35,ISNUMBER(SEARCH("XC",C10)),$X$37,ISNUMBER(SEARCH("UD",C10)),$X$36,ISNUMBER(SEARCH("-",C10)),0)} -> 0 | E10: {=_xlfn.IFS(ISNUMBER(SEARCH("RC",C10)),$X$26*0.001*$X$27*0.001*$X$30,ISNUMBER(SEARCH("XC",C10)),$X$26*0.001*$X$27*0.001*$X$32,ISNUMBER(SEARCH("UD",C10)),$X$26*0.001*$X$27*0.001*$X$31,ISNUMBER(SEARCH("-",C10)),0)} -> 0 | F10: {=_xlfn.IFS(ISNUMBER(SEARCH("RC",C10)),E10/(1-$Z$35),ISNUMBER(SEARCH("UD",C10)),E10/(1-$Z$36),ISNUMBER(SEARCH("UD",C10)),E10/(1-$Z$37),ISNUMBER(SEARCH("-",C10)),0)} -> 0 | G10: {=_xlfn.IFS( C10="-", 0, ISNUMBER(SEARCH($W$16,C10)), E10*0, ISNUMBER(SEARCH($W$17,C10)), E10*0.5, ISNUMBER(SEARCH($W$23,C10)), E10*0.5, ISNUMBER(SEARCH($W$22,C10)), E10*0, ISNUMBER(SEARCH($W$18,C10)), E10*1, OR(ISNUMBER(SEARCH($W$19,C10)),ISNUMBER(SEARCH($W$20,C10)),ISNUMBER(SEARCH($W$21,C10))), E10*0, TRUE, 0)} -> 0 | I10: x2 [mm] | J10: =IF(VLOOKUP(J7,'Base de Datos Probetas'!B6:M1000,8,FALSE)=0,"-",VLOOKUP(J7,'Base de Datos Probetas'!B6:M1000,8,FALSE)) -> 3.509643 | K10: y2 [N] | L10: =IF(VLOOKUP(J7,'Base de Datos Probetas'!B6:M1000,10,FALSE)=0,"-",VLOOKUP(J7,'Base de Datos Probetas'!B6:M1000,10,FALSE)) -> 11511.62 | P10: Perimeter Shear [N] | W10: y1 | X10: =X6/2 -> 0.59 | Y10: Ic1 | Z10: =Z8+(X8*(X12-X10)^2) -> 32875.496
B11: Capa 3 | C11: {=_xlfn.LET( _xlpm.texto_laminado, VLOOKUP($J$7, 'Base de Datos Probetas'!$B$6:$G$1000, 6, FALSE), _xlpm.limpio, SUBSTITUTE(SUBSTITUTE(SUBSTITUTE(_xlpm.texto_laminado, "[", ""), "]", ""), " S.", ""), _xlpm.capas, _xlfn.TEXTSPLIT(_xlpm.limpio, "/"), _xlpm.num_capas, COUNTA(_xlpm.capas), _xlpm.indice_capa, _xlpm.num_capas - (13 - ROW()), IF(OR(_xlpm.indice_capa < 1, _xlpm.indice_capa > _xlpm.num_capas), "-", _xlfn.LET( _xlpm.val, INDEX(_xlpm.capas, 1, _xlpm.indice_capa), IF(_xlpm.val="+-45", "RC +-45º", IF(_xlpm.val="+-90", "RC +-90º", IF(_xlpm.val="0", "UD 0º", _xlpm.val))) ) ) )} -> RC +-90º | D11: {=_xlfn.IFS(ISNUMBER(SEARCH("RC",C11)),$X$35,ISNUMBER(SEARCH("XC",C11)),$X$37,ISNUMBER(SEARCH("UD",C11)),$X$36,ISNUMBER(SEARCH("-",C11)),0)} -> 0.44 | E11: {=_xlfn.IFS(ISNUMBER(SEARCH("RC",C11)),$X$26*0.001*$X$27*0.001*$X$30,ISNUMBER(SEARCH("XC",C11)),$X$26*0.001*$X$27*0.001*$X$32,ISNUMBER(SEARCH("UD",C11)),$X$26*0.001*$X$27*0.001*$X$31,ISNUMBER(SEARCH("-",C11)),0)} -> 57.2 | F11: {=_xlfn.IFS(ISNUMBER(SEARCH("RC",C11)),E11/(1-$Z$35),ISNUMBER(SEARCH("UD",C11)),E11/(1-$Z$36),ISNUMBER(SEARCH("UD",C11)),E11/(1-$Z$37),ISNUMBER(SEARCH("-",C11)),0)} -> 95.333333 | G11: {=_xlfn.IFS( C11="-", 0, ISNUMBER(SEARCH($W$16,C11)), E11*0, ISNUMBER(SEARCH($W$17,C11)), E11*0.5, ISNUMBER(SEARCH($W$23,C11)), E11*0.5, ISNUMBER(SEARCH($W$22,C11)), E11*0, ISNUMBER(SEARCH($W$18,C11)), E11*1, OR(ISNUMBER(SEARCH($W$19,C11)),ISNUMBER(SEARCH($W$20,C11)),ISNUMBER(SEARCH($W$21,C11))), E11*0, TRUE, 0)} -> 28.6 | I11: Gradient [N/mm] | J11: =IFERROR(((L10-L9)/(J10-J9)),"-") -> 3604.87 | K11: Ymax [N] | L11: =IF(VLOOKUP(J7,'Base de Datos Probetas'!B6:M1000,11,FALSE)=0,"-",VLOOKUP(J7,'Base de Datos Probetas'!B6:M1000,11,FALSE)) -> 20742.53 | O11: Panel | P11: =IF(I7="FBH",(AB29+AB30)*0.002*(D18/1000)*P8*10^6,"Not Needed") -> Not Needed | W11: y2 | X11: =((D14+SUM(D6:D13)*2)-0.5*D18) -> 21.77 | Y11: Ic2 | Z11: =Z9+(X9*(X12-X11)^2) -> 32875.496
B12: Capa 2 | C12: {=_xlfn.LET( _xlpm.texto_laminado, VLOOKUP($J$7, 'Base de Datos Probetas'!$B$6:$G$1000, 6, FALSE), _xlpm.limpio, SUBSTITUTE(SUBSTITUTE(SUBSTITUTE(_xlpm.texto_laminado, "[", ""), "]", ""), " S.", ""), _xlpm.capas, _xlfn.TEXTSPLIT(_xlpm.limpio, "/"), _xlpm.num_capas, COUNTA(_xlpm.capas), _xlpm.indice_capa, _xlpm.num_capas - (13 - ROW()), IF(OR(_xlpm.indice_capa < 1, _xlpm.indice_capa > _xlpm.num_capas), "-", _xlfn.LET( _xlpm.val, INDEX(_xlpm.capas, 1, _xlpm.indice_capa), IF(_xlpm.val="+-45", "RC +-45º", IF(_xlpm.val="+-90", "RC +-90º", IF(_xlpm.val="0", "UD 0º", _xlpm.val))) ) ) )} -> UD 0º | D12: {=_xlfn.IFS(ISNUMBER(SEARCH("RC",C12)),$X$35,ISNUMBER(SEARCH("XC",C12)),$X$37,ISNUMBER(SEARCH("UD",C12)),$X$36,ISNUMBER(SEARCH("-",C12)),0)} -> 0.3 | E12: {=_xlfn.IFS(ISNUMBER(SEARCH("RC",C12)),$X$26*0.001*$X$27*0.001*$X$30,ISNUMBER(SEARCH("XC",C12)),$X$26*0.001*$X$27*0.001*$X$32,ISNUMBER(SEARCH("UD",C12)),$X$26*0.001*$X$27*0.001*$X$31,ISNUMBER(SEARCH("-",C12)),0)} -> 41.25 | F12: {=_xlfn.IFS(ISNUMBER(SEARCH("RC",C12)),E12/(1-$Z$35),ISNUMBER(SEARCH("UD",C12)),E12/(1-$Z$36),ISNUMBER(SEARCH("UD",C12)),E12/(1-$Z$37),ISNUMBER(SEARCH("-",C12)),0)} -> 63.461538 | G12: {=_xlfn.IFS( C12="-", 0, ISNUMBER(SEARCH($W$16,C12)), E12*0, ISNUMBER(SEARCH($W$17,C12)), E12*0.5, ISNUMBER(SEARCH($W$23,C12)), E12*0.5, ISNUMBER(SEARCH($W$22,C12)), E12*0, ISNUMBER(SEARCH($W$18,C12)), E12*1, OR(ISNUMBER(SEARCH($W$19,C12)),ISNUMBER(SEARCH($W$20,C12)),ISNUMBER(SEARCH($W$21,C12))), E12*0, TRUE, 0)} -> 41.25 | O12: Objetivo | P12: =IF(P11="Not Needed","Not Needed",510000) -> Not Needed | T12: UTS [N] | W12: Centroid | X12: =(X8*X10+X9*X11)/(X8+X9) -> 11.18 | Y12: Ic12 | Z12: =Z10+Z11 -> 65750.992
B13: Capa 1 | C13: {=_xlfn.LET( _xlpm.texto_laminado, VLOOKUP($J$7, 'Base de Datos Probetas'!$B$6:$G$1000, 6, FALSE), _xlpm.limpio, SUBSTITUTE(SUBSTITUTE(SUBSTITUTE(_xlpm.texto_laminado, "[", ""), "]", ""), " S.", ""), _xlpm.capas, _xlfn.TEXTSPLIT(_xlpm.limpio, "/"), _xlpm.num_capas, COUNTA(_xlpm.capas), _xlpm.indice_capa, _xlpm.num_capas - (13 - ROW()), IF(OR(_xlpm.indice_capa < 1, _xlpm.indice_capa > _xlpm.num_capas), "-", _xlfn.LET( _xlpm.val, INDEX(_xlpm.capas, 1, _xlpm.indice_capa), IF(_xlpm.val="+-45", "RC +-45º", IF(_xlpm.val="+-90", "RC +-90º", IF(_xlpm.val="0", "UD 0º", _xlpm.val))) ) ) )} -> RC +-45º | D13: {=_xlfn.IFS(ISNUMBER(SEARCH("RC",C13)),$X$35,ISNUMBER(SEARCH("XC",C13)),$X$37,ISNUMBER(SEARCH("UD",C13)),$X$36,ISNUMBER(SEARCH("-",C13)),0)} -> 0.44 | E13: {=_xlfn.IFS(ISNUMBER(SEARCH("RC",C13)),$X$26*0.001*$X$27*0.001*$X$30,ISNUMBER(SEARCH("XC",C13)),$X$26*0.001*$X$27*0.001*$X$32,ISNUMBER(SEARCH("UD",C13)),$X$26*0.001*$X$27*0.001*$X$31,ISNUMBER(SEARCH("-",C13)),0)} -> 57.2 | F13: {=_xlfn.IFS(ISNUMBER(SEARCH("RC",C13)),E13/(1-$Z$35),ISNUMBER(SEARCH("UD",C13)),E13/(1-$Z$36),ISNUMBER(SEARCH("UD",C13)),E13/(1-$Z$37),ISNUMBER(SEARCH("-",C13)),0)} -> 95.333333 | G13: {=_xlfn.IFS( C13="-", 0, ISNUMBER(SEARCH($W$16,C13)), E13*0, ISNUMBER(SEARCH($W$17,C13)), E13*0.5, ISNUMBER(SEARCH($W$23,C13)), E13*0.5, ISNUMBER(SEARCH($W$22,C13)), E13*0, ISNUMBER(SEARCH($W$18,C13)), E13*1, OR(ISNUMBER(SEARCH($W$19,C13)),ISNUMBER(SEARCH($W$20,C13)),ISNUMBER(SEARCH($W$21,C13))), E13*0, TRUE, 0)} -> 0 | O13: Coeficiente de Seguridad | P13: =IF(P11="Not Needed","Not Needed",P11/P12) -> Not Needed | S13: Probeta | T13: =AB27*AB5/1000000 -> 186414.24
B14: CORE | D14: =IF(VLOOKUP(J7,'Base de Datos Probetas'!B6:O1000,3,FALSE)=0,"N/A",VLOOKUP(J7,'Base de Datos Probetas'!B6:O1000,3,FALSE)) -> 20 | E14: {=_xlfn.LET( _xlpm.sel,$J$7, _xlpm.material,_xlfn.XLOOKUP(_xlpm.sel,'Base de Datos Probetas'!$B:$B,'Base de Datos Probetas'!$C:$C,""), IF( ISNUMBER(SEARCH("HC",_xlpm.material)), X40*1000*(D14/1000)*X26*0.001*X27*0.001, IF( ISNUMBER(SEARCH("Balsa",_xlpm.material)), X41*1000*(D14/1000)*X26*0.001*X27*0.001, "" ) ) )} -> 198.275 | F14: =E14 -> 198.275 | G14: - | J14: INERCIA DE LA PROBETA | L14: INERCIA DEL PANEL | S14: Objetivo | T14: {=_xlfn.IFS( I7="FBH", 87300, I7="FHB", 43700, I7="FBHS", 99900, I7="SHB", 63300, I7="MHBS", 66600, I7="SISv", 131000, I7="SISh", 131000)} -> 66600
I15: [mm^4] | J15: =(1/12)*(X27*(((D14+SUM(D6:D13)*2)^3)-(D14^3))) -> 72859.423 | L15: =Z12 -> 65750.992 | S15: Coeficiente de Seguridad | T15: =IF(OR(I7="SISv",I7="SISh"),"NA",T13/T14) -> 2.7990126 | W15: NUM | X15: nº Capas | Y15: % a 0 | Z15: DEN
B16: VALORES TOTALES PROBETA | D16: =_xlfn.CONCAT((D14+SUM(D6:D13)*2)," mm") -> 22,36 mm | E16: =_xlfn.CONCAT(E14+SUM(E6:E13)*2," g") -> 509,575 g | F16: =SUM(F6:F13)*2+F14 -> 706.53141 | G16: =_xlfn.CONCAT(SUM(G6:G13)*2, " g") -> 139,7 g | I16: [m^4] | J16: =J15/10^12 -> 7.2859423e-08 | L16: =L15/10^12 -> 6.5750992e-08 | O16: All other parameters | W16: RC +-45º | X16: =COUNTIF($C$6:$C$14,W16) -> 1 | Y16: =X16*0.5 -> 0.5 | Z16: =8-COUNTIF(C6:C13,"") -> 8
C17: Espesor Core [mm] | D17: =D14 -> 20 | O17: Yield Tensile Strength [N] | Q17: =IFERROR(T9,"-") -> 3.3467548 | W17: RC +-90º | X17: =COUNTIF($C$6:$C$14,W17) -> 1 | Y17: =X17*0.5 -> 0.5
C18: Espesor Piel [mm] | D18: =((D14+SUM(D6:D13)*2)-D14)/2 -> 1.18 | J18: E [Gpa] | K18: =IFERROR((J11*(J10-J9)*AB24^3)/(48*AB4*(J10-J9))*0.001,"-") -> 65.969414 | O18: UTS [N] | Q18: =IFERROR(T15,"-") -> 2.7990126 | T18: Max Load at Midspan [N] | W18: UD 0º | X18: =COUNTIF($C$6:$C$14,W18) -> 1 | Y18: =X18*1 -> 1
O19: Max Load at Midspan [N] | Q19: =IFERROR(T21,"-") -> 4.8620294 | S19: Probeta | T19: =4*AB5*L16/(0.001*0.5*(D17+2*D18)) -> 7487.5253 | W19: UD +45º | X19: =COUNTIF($C$6:$C$14,W19) -> 0 | Y19: =X19*0 -> 0
B20: PORCENTAJE TOTAL 0º | E20: WARPING % | K20: EI [Gpa/m^4] | O20: Max Deflection at baseline [m] | Q20: =IFERROR(T27,"-") -> 0.61638676 | S20: Objetivo | T20: {=_xlfn.IFS( I7="FBH", 1960, I7="FHB", 978, I7="FBHS", 2310, I7="SHB", 1330, I7="MHBS", 1540, I7="SISv", 2930, I7="SISh", 2930)} -> 1540 | W20: UD -45º | X20: =COUNTIF($C$6:$C$14,W20) -> 0 | Y20: =X20*0 -> 0
B21: =(SUM(G6:G13)/SUM(E6:E13)) -> 0.44876325 | E21: =ABS((SUMIF(C6:C13,"UD 0º",G6:G13)-((X26*0.001*X27*0.001)*X31*X21))/SUM(E6:E13)) -> 0.26501767 | J21: Panel | K21: =IFERROR(IF(J10-J9<1,"Distancia entre x1 y x2 < 1mm",K18*10^9*L16),"-") -> 4337.5544 | O21: Energy absorbed [J] | Q21: =IFERROR(T33,"-") -> 14.602578 | S21: Coeficiente de Seguridad | T21: =IF(OR(I7="SISv",I7="SISh"),"NA",T19/T20) -> 4.8620294 | W21: UD 90º | X21: =COUNTIF($C$6:$C$14,W21) -> 0 | Y21: =X21*0 -> 0
J22: Objetivo | K22: {=_xlfn.IFS( I7="FBH", 3400, I7="FHB", 1700, I7="FBHS", 4020, I7="SHB", 2320, I7="MHBS", 2680, I7="SISv", 5110, I7="SISh", 5110)} -> 2680 | W22: XC +-45º | X22: =COUNTIF($C$6:$C$14,W22) -> 0 | Y22: =X22*0.5 -> 0
J23: Coeficiente de Seguridad | K23: =IFERROR(K21/K22,"-") -> 1.6184905 | W23: XC +-90º | X23: =COUNTIF($C$6:$C$14,W23) -> 0 | Y23: =X23*0.5 -> 0
T24: Max Deflection at baseline [m] | AA24: Distancia entre apoyos del rig [mm] | AB24: 400
J25: {=_xlfn.IFS( I7="", "Elige un panel", I7="FHB", " ", I7="FBHS", " ", I7="SHB", " ", I7="MHBS", " ", I7="FBH", "La calculadora no hace 3PB para FBH", I7="SISv", "Calma, Falta sumarle el SISh, van en pack y el EI Objetivo es la suma del EI de ambos paneles", I7="SISh", "Calma, Falta sumarle el SISh, van en pack y el EI Objetivo es la suma del EI de ambos paneles")} | S25: Probeta | T25: =T20/(48*K21) -> 0.0073966411 | W25: DIMENSIONES PROBETA [mm]
S26: Objetivo | T26: {=_xlfn.IFS( I7="FBH", 0.012, I7="FHB", 0.012, I7="FBHS", 0.012, I7="SHB", 0.012, I7="MHBS", 0.012, I7="SISv", 0.012, I7="SISh", 0.012)} -> 0.012 | W26: Ancho | X26: 500
S27: Coeficiente de Seguridad | T27: =IF(OR(I7="SISv",I7="SISh"),"NA",T25/T26) -> 0.61638676 | W27: Largo | X27: 275 | AA27: Area | AB27: =((D17+2*D18)-D17)*L7 -> 585.6812
W29: Gramaje [g*m^2] | AA29: FBH Width | AB29: 313.98
T30: Energy absorbed [J] | W30: RC | X30: 416 | AA30: FBH Height | AB30: 314
S31: Probeta | T31: =0.5*T19*(T19/(48*K21)) -> 134.63576 | W31: UD | X31: 300 | AA31: Cutout Width | AB31: 165
S32: Objetivo | T32: {=_xlfn.IFS( I7="FBH", 11.7, I7="FHB", 5.86, I7="FBHS", 13.8, I7="SHB", 7.98, I7="MHBS", 9.22, I7="SISv", 17.6, I7="SISh", 17.6)} -> 9.22 | W32: XC | X32: 416 | AA32: Cutout Heigt | AB32: 165
S33: Coeficiente de Seguridad | T33: =IF(OR(I7="SISv",I7="SISh"),"NA",T31/T32) -> 14.602578
W34: Espesores [mm] | Y34: Porcentaje de Resina
W35: RC | X35: 0.44 | Y35: RC | Z35: 0.4
W36: UD | X36: 0.3 | Y36: UD | Z36: 0.35
W37: XC | X37: 0.6 | Y37: XC
W39: Densidad [kg/m^3]
W40: HC | X40: 72.1
W41: Balsa | X41: 155
W43: Pannel Heights [mm]
W44: FBH | X44: 149.98
W45: FHB | X45: 121.68
...

Sheet Tiradas Probetas MFT06
B2: LAMINADOS 05 | F2: LAMINADOS v1 | K2: COEFICIENTES MFT05
B3: FBH | C3: [RC200(45)/0/+-45/+-90/0/+-45/+-90/+-45] Core | F3: LAMINADO | G3: COMENTARIO | K3: FHB | L3: 1.37
B4: FHB | C4: [RC200T(45)/0/+-45/+-90/+-45/+-90] Core | F4: [+-45/0/+-45/+-90/+-45/+-90] Core | G4: Laminado FHB y FBHS 05 | H4: 2026-P01-01 | K4: FBHS | L4: 1.08
B5: FBHS | C5: [RC200T(45)/0/+-45/+-90/+-45/+-90] Core | F5: [+-45/0/+-45/+-90/0/+-45] Core | G5: Laminado SISh y SISv 05 | H5: 2026-P01-02 | K5: SISv | L5: 1.17
B6: SISh | C6: [RC200(45)/0/+-45/+-90/0/+-45] Core | F6: [+-45/0/+-45/+-90/+-45/+-90/+-45/+-90] Core | G6: Laminado SHB y MHBS 05 | H6: 2026-P01-03 | K6: SISh | L6: 1.17
B7: SISv | C7: [RC200(45)/0/+-45/+-90/0/+-45] Core | F7: [+-45/0/+-45/0/+-45/+-90/+-45/+-90] Core | G7: SHB y MHBS optimizado | K7: MHBS | L7: 1.47
B8: SHB | C8: [RC200T(45)/0/+-45/+-90/+-45/+-90/+-45/+-90] Core | F8: [RC200(45)/0/+-45/+-90/0/+-45/+-90/+-45] Core | G8: FBH 05 | K8: SHB | L8: 1.03
B9: MHBS | C9: [RC200T(45)/0/+-45/+-90/+-45/+-90/+-45/+-90] Core | F9: [RC200(45)/0/+-45/+-90/+-45/+-90/+-45] Core | G9: FBH Optimizado | K9: FBH | L9: 1.25
B11: LAMINADOS 06 | F11: LAMINADOS v2
B12: FBH | C12: [+-45/0/+-45/+-90/0/+-45] S. | F12: LAMINADO | G12: COMENTARIO | K12: Núm. 45º | L12: Núm. 90º
B13: FHB | C13: [+-90/0/+-45] S. | E13: 3PB | F13: [+-45/0/+-45/0/+-45] S. | G13: 5 Capas | H13: 2026-P02-01 | K13: 6 | L13: 0
B14: FBHS | C14: [+-90/0/+-45] S. | F14: [+-45/0/+-45/+-90] S. | G14: 4 Capas | H14: 2026-P02-02 | K14: 4 | L14: 2
B15: SISh | C15: [+-90/0/+-45] S. | F15: [+-90/0/+-45] S. | G15: 3 Capas | H15: 2026-P02-03 | K15: 2 | L15: 2
B16: SISv | C16: [+-45/0/+-45/0/+-45] S. | E16: Shear | F16: [+-45/0/+-45/+-90/+-45/+-90] | G16: FBH Shear 5 y 6 Capas (espesor equivalente a 7 y 8 del año pasado) | H16: 2026-P02-S01 | J16: TOTAL | K16: =SUM(K13:K15) -> 12 | L16: =SUM(L13:L15) -> 4
B17: SHB | C17: [+-45/0/+-45/0/+-45] S. | F17: [+-45/0/+-45/+-90/+-45] | H17: 2026-P02-S02 | J17: Nº Rollos | K17: =K16/3 -> 4 | L17: =L16/4 -> 1 | M17: =L17+K17 -> 5
B18: MHBS | C18: [+-90/0/+-45] S.
F19: LAMINADOS v3
F20: LAMINADO | G20: COMENTARIO | K20: Núm. 45º | L20: Núm. 90º
E21: 3PB | F21: [+-45/0/+-45/+-90/0/+-45/+-90/+-45] S. | G21: 8 Capas FBH | H21: 2026-P03-01 | K21: 8 | L21: 4
E22: Shear | F22: [+-45/0/+-45/+-90/0/+-45/+-90/+-45] S. | G22: 8 Capas FBH | H22: 2026-P03-S01 | J22: TOTAL | K22: =SUM(K21:K21) -> 8 | L22: =SUM(L21:L21) -> 4
F23: [+-45/0/+-45/0/+-45] S. | G23: Shear SHB/SISv | H23: 2026-P03-S02 | J23: Nº Rollos | K23: =K22/3 -> 2.6666667 | L23: =L22/4 -> 1 | M23: =L23+K23 -> 3.6666667
F24: [+-90/0/+-45] S. | G24: Shear FHB / FBHS / SISh / MHBS | H24: 2026-P03-S03
E25: Harness | F25: [+-45/0/+-45/0/+-45] S. | G25: Argolla - 5 Core 5 | H25: 2026-P03-L01
F26: [+-45/0/+-45/0/+-45] S. | G26: Shoulder Harness | H26: 2026-P03-H01
F28: LAMINADOS v4
E29: 3PB | F29: [+-45/0/+-45/+-90/0/+-45] S. | G29: 6 Capas FBH | H29: 2026-P04-01
E30: Shear | F30: [+-45/0/+-45/+-90/0/+-45] S. | G30: 6 Capas FBH | H30: 2026-P04-S01

Sheet Peso Monocasco
B2: PESO MONOCASCO | F2: Area [mm^2]
B3: Panel | C3: Peso real de la probeta [g] | D3: Peso Real del laminado en el monocasco [g] | F3: FBH | G3: 60798.57
B4: FBH | C4: 128 | D4: =(C4/$G$12)*G3 -> 778.2217 | F4: FHB | G4: 433988.68
B5: FHB | C5: 868 | D5: =(C5/$G$11)*G4 -> 2739.6522 | F5: FBHS | G5: 372409.54
B6: FBHS | C6: 868 | D6: =(C6/$G$11)*G5*2 -> 4701.8397 | F6: SISh | G6: 1110232.3
B7: SISh | C7: 868 | D7: =(C7/$G$11)*G6 -> 7008.5938 | F7: SISv | G7: 287720.74
B8: SISv | C8: 1162 | D8: =(C8/$G$11)*G7*2 -> 4863.0036 | F8: MHBS | G8: 328335.11
B9: MHBS | C9: 868 | D9: =(C9/$G$11)*G8*2 -> 4145.38 | F9: SHB | G9: 96160.39
B10: SHB | C10: 1162 | D10: =(C10/$G$11)*G9 -> 812.64271 | F10: Dashboard | G10: 31463.69
F11: 3PB | G11: ='Calculadora SES'!X26*'Calculadora SES'!X27 -> 137500
C12: PESO TOTAL REAL [kg] | D12: =(SUM(D4:D10)+G15+G19)/1000 -> 25.235459 | F12: Shear | G12: =100*100 -> 10000
F15: Peso Dashboard R | G15: =((D5-198.28)/'Peso Monocasco'!G4)*'Peso Monocasco'!G10 -> 184.24662
F17: Densidad DC01 [kg/mm3] | G17: 7.85e-06
F18: Volumen FH [mm3] | G18: 239266
F19: Peso DC01 | G19: =G18*G17 -> 1.8782381

Sheet Desplegables
C3: RC +-45º | E3: FBH | G3: 3PB
C4: RC +-90º | E4: FHB | G4: Shear
C5: UD 0º | E5: FBHS | G5: Lap Belt Parallel
C6: UD +45º | E6: SISv | G6: Lap Belt Perp.
C7: UD -45º | E7: SISh | G7: Harness
C8: UD 90º | E8: MHBS
C9: XC +-45º | E9: SHB
C10: XC +-90º
C11: -
